```
try
{
    program-statement
}
catch (exception-declaration)
{
    handle-statement
}
catch (exception-declaration)
{ 
    handle-statement
}
```
抛出异常 捕获异常
```cpp
while (cin >> item1 >> item2)
{
    try
    {
        if (item1.isbn() != item2.isbn())
            throw runtime_error("Data must refer to same ISBN");
        std::cout << item1 + item2 << std::endl;
    }
    catch (runtime_error err)
    {
        cout << err.what() << "\nTry Again? Enter y or n" << endl;
        char c;
        cin >> c;
        if (!cin || c == 'n')
            break;
    }
    
}
```
在多个嵌套语句中抛出异常后 搜寻异常函数 如果没找到匹配的`catch`语句 终止该函数 在调用函数的函数中继续寻找 如果还没找到该函数也终止 继续搜索调用它的函数
如果最终都未找到 程序转为`terminate`的标准库函数 一般该函数会导致程序异常退出 没有`try`的默认照此执行 即调用`terminate`函数终止程序运行

编写异常安全的代码非常困难 因为调用者的请求可能一部分计算好了 另一部分没有完成 对象可能处于无效或未完成的状态 或者资源木有释放
应该特别注意 如何确保对象有效 资源无泄漏 程序处于合理的状态等